<robot name="simple_robot">
    <material name="gray">
        <color rgba="0.5 0.5 0.5 1.0"/>
    </material> 

    <material name="blue">
        <color rgba="0 0 1 1.0"/>
    </material>


    <link name="base_link"> 
        <visual>
            <origin xyz="0 0 0" rpy="0 0 0"/> 
            <geometry> 
                <box size="0.3 0.3 0.3"/>
            </geometry> 
            <material name="gray"/>
        </visual> 
    </link>

    <link name="first_cylinder">
        <visual>
            <origin xyz="0 0 0.25" rpy="0 0 0"/>
            <geometry>
                <cylinder radius="0.05" length="0.5"/>
            </geometry>
            <material name="blue"/>
        </visual> 
    </link>

    <link name="second_cylinder">
        <visual>
            <origin xyz="0 0 0.125" rpy="0 0 0"/>
            <geometry>
                <cylinder radius="0.05" length="0.25"/>
            </geometry>
            <material name="blue"/>
        </visual>
    </link>

    <link name="third_cylinder">
        <visual>
            <origin xyz="0 0 0.125" rpy="0 0 0"/>
            <geometry>
                <cylinder radius="0.05" length="0.25"/>
            </geometry>
            <material name="gray"/>
        </visual>
    </link>

    <link name="fourth_cylinder">
        <visual>
            <origin xyz="0 0 0.125" rpy="0 0 0"/>
            <geometry>
                <cylinder radius="0.05" length="0.25"/>
            </geometry>
            <material name="gray"/>
        </visual>
    </link>

    <link name="link_1_sphere">
        <visual>
            <origin xyz="0 0 0" rpy="0 0 0"/>
            <geometry>
                <sphere radius="0.06"/>
            </geometry>
            <material name="gray"/>
        </visual>
    </link>

    <link name="link_2_sphere">
        <visual>
            <origin xyz="0 0 0" rpy="0 0 0"/>
            <geometry>
                <sphere radius="0.06"/>
            </geometry>
            <material name="blue"/>
        </visual>
    </link>

    <link name="end_effector">
    </link>




    <joint name="fixed_link1_to_sphere1" type="fixed">
        <parent link="first_cylinder"/>
        <child link="link_1_sphere"/>
        <origin xyz="0 0 0.5" rpy="0 0 0"/>
    </joint>


    <joint name="joint0" type="revolute">
        <parent link="base_link"/>
        <child link="first_cylinder"/>
        <origin xyz="0 0 0.15" rpy="0 0 0"/>
        <axis xyz="0 0 1"/>
        <limit lower="-1.5707963267948966" upper="1.5707963267948966" effort="10.0" velocity="1.0"/>
    </joint>

    <joint name="joint1" type="revolute">
        <parent link="link_1_sphere"/>
        <child link="second_cylinder"/>
        <origin xyz="0 0 0" rpy="0 0 0"/>
        <axis xyz="1 0 0"/>
        <limit lower="-1.5707963267948966" upper="1.5707963267948966" effort="10.0" velocity="1.0"/>
    </joint>

    <joint name="joint2" type="revolute">
        <parent link="second_cylinder"/>
        <child link="third_cylinder"/>
        <origin xyz="0 0 0.25" rpy="0 0 0"/>
        <axis xyz="0 0 1"/>
        <limit lower="-1.5707963267948966" upper="1.5707963267948966" effort="10.0" velocity="1.0"/>
    </joint>

    <joint name="joint3" type="revolute">
        <parent link="link_2_sphere"/>
        <child link="fourth_cylinder"/>
        <origin xyz="0 0 0" rpy="0 0 0"/>
        <axis xyz="1 0 0"/>
        <limit lower="-1.5707963267948966" upper="1.5707963267948966" effort="10.0" velocity="1.0"/>
    </joint>

    <joint name="fixed_link3_to_sphere2" type="fixed">
        <parent link="third_cylinder"/>
        <child link="link_2_sphere"/>
        <origin xyz="0 0 0.25" rpy="0 0 0"/>
    </joint>

    <joint name="fixed_fourth_cylinder_to_ee" type="fixed">
        <parent link="fourth_cylinder"/>
        <child link="end_effector"/>
        <origin xyz="0 0 0.25" rpy="0 0 0"/>
    </joint>

</robot>




